2019-07-12 18:04:39,159 exception.py [line:135] ERROR Internal Server Error: /home/
Traceback (most recent call last):
  File "C:\Python\Python36\lib\site-packages\django\utils\datastructures.py", line 83, in __getitem__
    list_ = super(MultiValueDict, self).__getitem__(key)
KeyError: 'excel'

During handling of the above exception, another exception occurred:

Traceback (most recent call last):
  File "C:\Python\Python36\lib\site-packages\django\core\handlers\exception.py", line 41, in inner
    response = get_response(request)
  File "C:\Python\Python36\lib\site-packages\django\core\handlers\base.py", line 187, in _get_response
    response = self.process_exception_by_middleware(e, request)
  File "C:\Python\Python36\lib\site-packages\django\core\handlers\base.py", line 185, in _get_response
    response = wrapped_callback(request, *callback_args, **callback_kwargs)
  File "E:\work_datum\800TS_Project\scheduling\scheduling\view_scheduling.py", line 40, in sehceduing
    excel = request.FILES['excel']
  File "C:\Python\Python36\lib\site-packages\django\utils\datastructures.py", line 85, in __getitem__
    raise MultiValueDictKeyError(repr(key))
django.utils.datastructures.MultiValueDictKeyError: "'excel'"
2019-07-12 18:52:48,777 exception.py [line:135] ERROR Internal Server Error: /home/
Traceback (most recent call last):
  File "C:\Python\Python36\lib\site-packages\django\utils\datastructures.py", line 83, in __getitem__
    list_ = super(MultiValueDict, self).__getitem__(key)
KeyError: 'excel'

During handling of the above exception, another exception occurred:

Traceback (most recent call last):
  File "C:\Python\Python36\lib\site-packages\django\core\handlers\exception.py", line 41, in inner
    response = get_response(request)
  File "C:\Python\Python36\lib\site-packages\django\core\handlers\base.py", line 187, in _get_response
    response = self.process_exception_by_middleware(e, request)
  File "C:\Python\Python36\lib\site-packages\django\core\handlers\base.py", line 185, in _get_response
    response = wrapped_callback(request, *callback_args, **callback_kwargs)
  File "E:\work_datum\800TS_Project\scheduling\scheduling\view_scheduling.py", line 40, in sehceduing
    excel = request.FILES['excel']
  File "C:\Python\Python36\lib\site-packages\django\utils\datastructures.py", line 85, in __getitem__
    raise MultiValueDictKeyError(repr(key))
django.utils.datastructures.MultiValueDictKeyError: "'excel'"
2019-07-12 18:53:03,480 exception.py [line:135] ERROR Internal Server Error: /home/
Traceback (most recent call last):
  File "C:\Python\Python36\lib\site-packages\django\utils\datastructures.py", line 83, in __getitem__
    list_ = super(MultiValueDict, self).__getitem__(key)
KeyError: 'excel'

During handling of the above exception, another exception occurred:

Traceback (most recent call last):
  File "C:\Python\Python36\lib\site-packages\django\core\handlers\exception.py", line 41, in inner
    response = get_response(request)
  File "C:\Python\Python36\lib\site-packages\django\core\handlers\base.py", line 187, in _get_response
    response = self.process_exception_by_middleware(e, request)
  File "C:\Python\Python36\lib\site-packages\django\core\handlers\base.py", line 185, in _get_response
    response = wrapped_callback(request, *callback_args, **callback_kwargs)
  File "E:\work_datum\800TS_Project\scheduling\scheduling\view_scheduling.py", line 40, in sehceduing
    excel = request.FILES['excel']
  File "C:\Python\Python36\lib\site-packages\django\utils\datastructures.py", line 85, in __getitem__
    raise MultiValueDictKeyError(repr(key))
django.utils.datastructures.MultiValueDictKeyError: "'excel'"
